Workbook

Sheet Calculator
B2: Retirement Savings Calculator
B4: INPUTS & ASSUMPTIONS | E4: YEAR-BY-YEAR PROJECTION
E5: Year | F5: Age | G5: Starting Balance | H5: Contribution | I5: Investment Return | J5: Inflation Adj. | K5: Ending Balance
B6: Current Age | C6: 30 | E6: 1 | F6: {=C6} -> 30 | G6: {=C8} -> 50000 | H6: {=C9} -> 12000 | I6: =(G6+H6)*C$11 -> 4340 | J6: =(G6+H6+I6)*C$12 -> 1658.5 | K6: =G6+H6+I6 -> 66340
B7: Retirement Age | C7: 65 | E7: 2 | F7: =F6+1 -> 31 | G7: {=K6} -> 66340 | H7: =H6*(1+C$10) -> 12360 | I7: =(G7+H7)*C$11 -> 5509 | J7: =(G7+H7+I7)*C$12 -> 2105.225 | K7: =G7+H7+I7 -> 84209
B8: Current Savings ($) | C8: 50000 | E8: 3 | F8: =F7+1 -> 32 | G8: {=K7} -> 84209 | H8: =H7*(1+C$10) -> 12730.8 | I8: =(G8+H8)*C$11 -> 6785.786 | J8: =(G8+H8+I8)*C$12 -> 2593.1397 | K8: =G8+H8+I8 -> 103725.59
B9: Annual Contribution ($) | C9: 12000 | E9: 4 | F9: =F8+1 -> 33 | G9: {=K8} -> 103725.59 | H9: =H8*(1+C$10) -> 13112.724 | I9: =(G9+H9)*C$11 -> 8178.6817 | J9: =(G9+H9+I9)*C$12 -> 3125.4248 | K9: =G9+H9+I9 -> 125016.99
B10: Annual Contribution Increase (%) | C10: 0.03 | E10: 5 | F10: =F9+1 -> 34 | G10: {=K9} -> 125016.99 | H10: =H9*(1+C$10) -> 13506.106 | I10: =(G10+H10)*C$11 -> 9696.6168 | J10: =(G10+H10+I10)*C$12 -> 3705.4929 | K10: =G10+H10+I10 -> 148219.71
B11: Expected Annual Return (%) | C11: 0.07 | E11: 6 | F11: =F10+1 -> 35 | G11: {=K10} -> 148219.71 | H11: =H10*(1+C$10) -> 13911.289 | I11: =(G11+H11)*C$11 -> 11349.17 | J11: =(G11+H11+I11)*C$12 -> 4337.0043 | K11: =G11+H11+I11 -> 173480.17
B12: Inflation Rate (%) | C12: 0.025 | E12: 7 | F12: =F11+1 -> 36 | G12: {=K11} -> 173480.17 | H12: =H11*(1+C$10) -> 14328.628 | I12: =(G12+H12)*C$11 -> 13146.616 | J12: =(G12+H12+I12)*C$12 -> 5023.8854 | K12: =G12+H12+I12 -> 200955.42
B13: Annual Retirement Spending ($) | C13: 60000 | E13: 8 | F13: =F12+1 -> 37 | G13: {=K12} -> 200955.42 | H13: =H12*(1+C$10) -> 14758.486 | I13: =(G13+H13)*C$11 -> 15099.973 | J13: =(G13+H13+I13)*C$12 -> 5770.3469 | K13: =G13+H13+I13 -> 230813.88
B14: Life Expectancy | C14: 90 | E14: 9 | F14: =F13+1 -> 38 | G14: {=K13} -> 230813.88 | H14: =H13*(1+C$10) -> 15201.241 | I14: =(G14+H14)*C$11 -> 17221.058 | J14: =(G14+H14+I14)*C$12 -> 6580.9044 | K14: =G14+H14+I14 -> 263236.18
E15: 10 | F15: =F14+1 -> 39 | G15: {=K14} -> 263236.18 | H15: =H14*(1+C$10) -> 15657.278 | I15: =(G15+H15)*C$11 -> 19522.542 | J15: =(G15+H15+I15)*C$12 -> 7460.3999 | K15: =G15+H15+I15 -> 298416
B16: SUMMARY | E16: 11 | F16: =F15+1 -> 40 | G16: {=K15} -> 298416 | H16: =H15*(1+C$10) -> 16126.997 | I16: =(G16+H16)*C$11 -> 22018.009 | J16: =(G16+H16+I16)*C$12 -> 8414.025 | K16: =G16+H16+I16 -> 336561
E17: 12 | F17: =F16+1 -> 41 | G17: {=K16} -> 336561 | H17: =H16*(1+C$10) -> 16610.806 | I17: =(G17+H17)*C$11 -> 24722.027 | J17: =(G17+H17+I17)*C$12 -> 9447.3459 | K17: =G17+H17+I17 -> 377893.83
B18: Years to Retirement | C18: =C7-C6 -> 35 | E18: 13 | F18: =F17+1 -> 42 | G18: {=K17} -> 377893.83 | H18: =H17*(1+C$10) -> 17109.131 | I18: =(G18+H18)*C$11 -> 27650.208 | J18: =(G18+H18+I18)*C$12 -> 10566.329 | K18: =G18+H18+I18 -> 422653.17
B19: Years in Retirement | C19: =C14-C7 -> 25 | E19: 14 | F19: =F18+1 -> 43 | G19: {=K18} -> 422653.17 | H19: =H18*(1+C$10) -> 17622.405 | I19: =(G19+H19)*C$11 -> 30819.29 | J19: =(G19+H19+I19)*C$12 -> 11777.372 | K19: =G19+H19+I19 -> 471094.87
B20: Real Return Rate (%) | C20: =(1+C11)/(1+C12)-1 -> 0.043902439 | E20: 15 | F20: =F19+1 -> 44 | G20: {=K19} -> 471094.87 | H20: =H19*(1+C$10) -> 18151.077 | I20: =(G20+H20)*C$11 -> 34247.216 | J20: =(G20+H20+I20)*C$12 -> 13087.329 | K20: =G20+H20+I20 -> 523493.16
B21: Savings at Retirement (Nominal) | C21: {=OFFSET(K5,C18,0)} -> 3057761.9 | E21: 16 | F21: =F20+1 -> 45 | G21: {=K20} -> 523493.16 | H21: =H20*(1+C$10) -> 18695.609 | I21: =(G21+H21)*C$11 -> 37953.214 | J21: =(G21+H21+I21)*C$12 -> 14503.55 | K21: =G21+H21+I21 -> 580141.98
B22: Savings at Retirement (Today's $) | C22: =C21/(1+C12)^C18 -> 1288452.4 | E22: 17 | F22: =F21+1 -> 46 | G22: {=K21} -> 580141.98 | H22: =H21*(1+C$10) -> 19256.477 | I22: =(G22+H22)*C$11 -> 41957.892 | J22: =(G22+H22+I22)*C$12 -> 16033.909 | K22: =G22+H22+I22 -> 641356.35
B23: Total Contributions | C23: {=SUMPRODUCT((E6:E40<=C18)*H6:H40)} -> 725544.98 | E23: 18 | F23: =F22+1 -> 47 | G23: {=K22} -> 641356.35 | H23: =H22*(1+C$10) -> 19834.172 | I23: =(G23+H23)*C$11 -> 46283.337 | J23: =(G23+H23+I23)*C$12 -> 17686.847 | K23: =G23+H23+I23 -> 707473.86
B24: Total Investment Growth | C24: =C21-C8-C23 -> 2282216.9 | E24: 19 | F24: =F23+1 -> 48 | G24: {=K23} -> 707473.86 | H24: =H23*(1+C$10) -> 20429.197 | I24: =(G24+H24)*C$11 -> 50953.214 | J24: =(G24+H24+I24)*C$12 -> 19471.407 | K24: =G24+H24+I24 -> 778856.27
B25: Required Nest Egg (Today's $) | C25: =C13*((1-(1/(1+C20))^C19)/C20) -> 899830.18 | E25: 20 | F25: =F24+1 -> 49 | G25: {=K24} -> 778856.27 | H25: =H24*(1+C$10) -> 21042.073 | I25: =(G25+H25)*C$11 -> 55992.884 | J25: =(G25+H25+I25)*C$12 -> 21397.281 | K25: =G25+H25+I25 -> 855891.23
B26: Surplus / (Shortfall) (Today's $) | C26: =C22-C25 -> 388622.21 | E26: 21 | F26: =F25+1 -> 50 | G26: {=K25} -> 855891.23 | H26: =H25*(1+C$10) -> 21673.335 | I26: =(G26+H26)*C$11 -> 61429.519 | J26: =(G26+H26+I26)*C$12 -> 23474.852 | K26: =G26+H26+I26 -> 938994.08
E27: 22 | F27: =F26+1 -> 51 | G27: {=K26} -> 938994.08 | H27: =H26*(1+C$10) -> 22323.535 | I27: =(G27+H27)*C$11 -> 67292.233 | J27: =(G27+H27+I27)*C$12 -> 25715.246 | K27: =G27+H27+I27 -> 1028609.9
E28: 23 | F28: =F27+1 -> 52 | G28: {=K27} -> 1028609.9 | H28: =H27*(1+C$10) -> 22993.241 | I28: =(G28+H28)*C$11 -> 73612.216 | J28: =(G28+H28+I28)*C$12 -> 28130.383 | K28: =G28+H28+I28 -> 1125215.3
E29: 24 | F29: =F28+1 -> 53 | G29: {=K28} -> 1125215.3 | H29: =H28*(1+C$10) -> 23683.038 | I29: =(G29+H29)*C$11 -> 80422.884 | J29: =(G29+H29+I29)*C$12 -> 30733.031 | K29: =G29+H29+I29 -> 1229321.2
E30: 25 | F30: =F29+1 -> 54 | G30: {=K29} -> 1229321.2 | H30: =H29*(1+C$10) -> 24393.529 | I30: =(G30+H30)*C$11 -> 87760.033 | J30: =(G30+H30+I30)*C$12 -> 33536.87 | K30: =G30+H30+I30 -> 1341474.8
E31: 26 | F31: =F30+1 -> 55 | G31: {=K30} -> 1341474.8 | H31: =H30*(1+C$10) -> 25125.335 | I31: =(G31+H31)*C$11 -> 95662.009 | J31: =(G31+H31+I31)*C$12 -> 36556.553 | K31: =G31+H31+I31 -> 1462262.1
E32: 27 | F32: =F31+1 -> 56 | G32: {=K31} -> 1462262.1 | H32: =H31*(1+C$10) -> 25879.095 | I32: =(G32+H32)*C$11 -> 104169.89 | J32: =(G32+H32+I32)*C$12 -> 39807.778 | K32: =G32+H32+I32 -> 1592311.1
E33: 28 | F33: =F32+1 -> 57 | G33: {=K32} -> 1592311.1 | H33: =H32*(1+C$10) -> 26655.468 | I33: =(G33+H33)*C$11 -> 113327.66 | J33: =(G33+H33+I33)*C$12 -> 43307.356 | K33: =G33+H33+I33 -> 1732294.2
E34: 29 | F34: =F33+1 -> 58 | G34: {=K33} -> 1732294.2 | H34: =H33*(1+C$10) -> 27455.132 | I34: =(G34+H34)*C$11 -> 123182.46 | J34: =(G34+H34+I34)*C$12 -> 47073.296 | K34: =G34+H34+I34 -> 1882931.8
E35: 30 | F35: =F34+1 -> 59 | G35: {=K34} -> 1882931.8 | H35: =H34*(1+C$10) -> 28278.786 | I35: =(G35+H35)*C$11 -> 133784.74 | J35: =(G35+H35+I35)*C$12 -> 51124.884 | K35: =G35+H35+I35 -> 2044995.4
E36: 31 | F36: =F35+1 -> 60 | G36: {=K35} -> 2044995.4 | H36: =H35*(1+C$10) -> 29127.15 | I36: =(G36+H36)*C$11 -> 145188.58 | J36: =(G36+H36+I36)*C$12 -> 55482.777 | K36: =G36+H36+I36 -> 2219311.1
E37: 32 | F37: =F36+1 -> 61 | G37: {=K36} -> 2219311.1 | H37: =H36*(1+C$10) -> 30000.964 | I37: =(G37+H37)*C$11 -> 157451.84 | J37: =(G37+H37+I37)*C$12 -> 60169.098 | K37: =G37+H37+I37 -> 2406763.9
E38: 33 | F38: =F37+1 -> 62 | G38: {=K37} -> 2406763.9 | H38: =H37*(1+C$10) -> 30900.993 | I38: =(G38+H38)*C$11 -> 170636.54 | J38: =(G38+H38+I38)*C$12 -> 65207.536 | K38: =G38+H38+I38 -> 2608301.4
... E40: 35 | F40: =F39+1 -> 64 | G40: {=K39} -> 2824938.5 | H40: =H39*(1+C$10) -> 32782.864 | I40: =(G40+H40)*C$11 -> 200040.5 | J40: =(G40+H40+I40)*C$12 -> 76444.047 | K40: =G40+H40+I40 -> 3057761.9
B42: SENSITIVITY ANALYSIS — Surplus / (Shortfall) in Today's $
B44: Inflation Rate → | D44: 0.01 | E44: 0.015 | F44: 0.02 | G44: 0.025 | H44: 0.03 | I44: 0.035 | J44: 0.04
C45: Return Rate ↓
...

Sheet Charts
A1: Age | B1: RETIREMENT SAVINGS — CHARTS | C1: Investment Growth | D1: Ending Balance | F1: Component | G1: Amount | I1: Age | J1: Annual Contribution | K1: Annual Return
A2: {=Calculator!F6} -> 30 | B2: =Calculator!H6+Calculator!C8 -> 62000 | C2: =Calculator!K6-B2 -> 4340 | D2: {=Calculator!K6} -> 66340 | F2: Initial Savings | G2: {=Calculator!C8} -> 50000 | I2: {=Calculator!F6} -> 30 | J2: {=Calculator!H6} -> 12000 | K2: {=Calculator!I6} -> 4340
A3: {=Calculator!F7} -> 31 | B3: =B2+Calculator!H7 -> 74360 | C3: =Calculator!K7-B3 -> 9849 | D3: {=Calculator!K7} -> 84209 | F3: Total Contributions | G3: {=Calculator!C23} -> 725544.98 | I3: {=Calculator!F7} -> 31 | J3: {=Calculator!H7} -> 12360 | K3: {=Calculator!I7} -> 5509
A4: {=Calculator!F8} -> 32 | B4: =B3+Calculator!H8 -> 87090.8 | C4: =Calculator!K8-B4 -> 16634.786 | D4: {=Calculator!K8} -> 103725.59 | F4: Investment Growth | G4: {=Calculator!C24} -> 2282216.9 | I4: {=Calculator!F8} -> 32 | J4: {=Calculator!H8} -> 12730.8 | K4: {=Calculator!I8} -> 6785.786
A5: {=Calculator!F9} -> 33 | B5: =B4+Calculator!H9 -> 100203.52 | C5: =Calculator!K9-B5 -> 24813.468 | D5: {=Calculator!K9} -> 125016.99 | I5: {=Calculator!F9} -> 33 | J5: {=Calculator!H9} -> 13112.724 | K5: {=Calculator!I9} -> 8178.6817
A6: {=Calculator!F10} -> 34 | B6: =B5+Calculator!H10 -> 113709.63 | C6: =Calculator!K10-B6 -> 34510.085 | D6: {=Calculator!K10} -> 148219.71 | I6: {=Calculator!F10} -> 34 | J6: {=Calculator!H10} -> 13506.106 | K6: {=Calculator!I10} -> 9696.6168
A7: {=Calculator!F11} -> 35 | B7: =B6+Calculator!H11 -> 127620.92 | C7: =Calculator!K11-B7 -> 45859.255 | D7: {=Calculator!K11} -> 173480.17 | I7: {=Calculator!F11} -> 35 | J7: {=Calculator!H11} -> 13911.289 | K7: {=Calculator!I11} -> 11349.17
A8: {=Calculator!F12} -> 36 | B8: =B7+Calculator!H12 -> 141949.55 | C8: =Calculator!K12-B8 -> 59005.871 | D8: {=Calculator!K12} -> 200955.42 | I8: {=Calculator!F12} -> 36 | J8: {=Calculator!H12} -> 14328.628 | K8: {=Calculator!I12} -> 13146.616
A9: {=Calculator!F13} -> 37 | B9: =B8+Calculator!H13 -> 156708.03 | C9: =Calculator!K13-B9 -> 74105.844 | D9: {=Calculator!K13} -> 230813.88 | I9: {=Calculator!F13} -> 37 | J9: {=Calculator!H13} -> 14758.486 | K9: {=Calculator!I13} -> 15099.973
A10: {=Calculator!F14} -> 38 | B10: =B9+Calculator!H14 -> 171909.27 | C10: =Calculator!K14-B10 -> 91326.902 | D10: {=Calculator!K14} -> 263236.18 | I10: {=Calculator!F14} -> 38 | J10: {=Calculator!H14} -> 15201.241 | K10: {=Calculator!I14} -> 17221.058
A11: {=Calculator!F15} -> 39 | B11: =B10+Calculator!H15 -> 187566.55 | C11: =Calculator!K15-B11 -> 110849.44 | D11: {=Calculator!K15} -> 298416 | I11: {=Calculator!F15} -> 39 | J11: {=Calculator!H15} -> 15657.278 | K11: {=Calculator!I15} -> 19522.542
A12: {=Calculator!F16} -> 40 | B12: =B11+Calculator!H16 -> 203693.55 | C12: =Calculator!K16-B12 -> 132867.45 | D12: {=Calculator!K16} -> 336561 | I12: {=Calculator!F16} -> 40 | J12: {=Calculator!H16} -> 16126.997 | K12: {=Calculator!I16} -> 22018.009
A13: {=Calculator!F17} -> 41 | B13: =B12+Calculator!H17 -> 220304.35 | C13: =Calculator!K17-B13 -> 157589.48 | D13: {=Calculator!K17} -> 377893.83 | I13: {=Calculator!F17} -> 41 | J13: {=Calculator!H17} -> 16610.806 | K13: {=Calculator!I17} -> 24722.027
A14: {=Calculator!F18} -> 42 | B14: =B13+Calculator!H18 -> 237413.49 | C14: =Calculator!K18-B14 -> 185239.69 | D14: {=Calculator!K18} -> 422653.17 | I14: {=Calculator!F18} -> 42 | J14: {=Calculator!H18} -> 17109.131 | K14: {=Calculator!I18} -> 27650.208
A15: {=Calculator!F19} -> 43 | B15: =B14+Calculator!H19 -> 255035.89 | C15: =Calculator!K19-B15 -> 216058.98 | D15: {=Calculator!K19} -> 471094.87 | I15: {=Calculator!F19} -> 43 | J15: {=Calculator!H19} -> 17622.405 | K15: {=Calculator!I19} -> 30819.29
A16: {=Calculator!F20} -> 44 | B16: =B15+Calculator!H20 -> 273186.97 | C16: =Calculator!K20-B16 -> 250306.19 | D16: {=Calculator!K20} -> 523493.16 | I16: {=Calculator!F20} -> 44 | J16: {=Calculator!H20} -> 18151.077 | K16: {=Calculator!I20} -> 34247.216
... A36: {=Calculator!F40} -> 64 | B36: =B35+Calculator!H40 -> 775544.98 | C36: =Calculator!K40-B36 -> 2282216.9 | D36: {=Calculator!K40} -> 3057761.9 | I36: {=Calculator!F40} -> 64 | J36: {=Calculator!H40} -> 32782.864 | K36: {=Calculator!I40} -> 200040.5

Sheet Scenarios
B2: Retirement Scenario Analysis
B4: Scenario | C4: Risk Profile | D4: Age Group | E4: Starting Age | F4: Retirement Age | G4: Initial Savings | H4: Annual Contribution | I4: Return Rate | J4: Inflation Rate | K4: Years to Retire | L4: Savings at Retirement | M4: Required Nest Egg | N4: Surplus / (Shortfall)
B5: Conservative Early Start | C5: Conservative | D5: Young (25-35) | E5: 25 | F5: 65 | G5: 20000 | H5: 8000 | I5: 0.04 | J5: 0.02 | K5: =F5-E5 -> 40 | L5: =(G5*(1+I5)^K5+H5*(((1+I5)^K5-(1+0.03)^K5)/(I5-0.03)))/(1+J5)^K5 -> 601079.18 | M5: =60000*((1-(1/(1+((1+I5)/(1+J5)-1)))^(90-F5))/((1+I5)/(1+J5)-1)) -> 1176818.2 | N5: =L5-M5 -> -575739.06
B6: Conservative Moderate Save | C6: Conservative | D6: Young (25-35) | E6: 28 | F6: 65 | G6: 30000 | H6: 10000 | I6: 0.04 | J6: 0.025 | K6: =F6-E6 -> 37 | L6: =(G6*(1+I6)^K6+H6*(((1+I6)^K6-(1+0.03)^K6)/(I6-0.03)))/(1+J6)^K6 -> 565867.85 | M6: =60000*((1-(1/(1+((1+I6)/(1+J6)-1)))^(90-F6))/((1+I6)/(1+J6)-1)) -> 1248673.1 | N6: =L6-M6 -> -682805.26
B7: Conservative Max Save | C7: Conservative | D7: Young (25-35) | E7: 30 | F7: 65 | G7: 50000 | H7: 15000 | I7: 0.045 | J7: 0.025 | K7: =F7-E7 -> 35 | L7: =(G7*(1+I7)^K7+H7*(((1+I7)^K7-(1+0.03)^K7)/(I7-0.03)))/(1+J7)^K7 -> 879339.37 | M7: =60000*((1-(1/(1+((1+I7)/(1+J7)-1)))^(90-F7))/((1+I7)/(1+J7)-1)) -> 1178143.4 | N7: =L7-M7 -> -298804.06
B8: Conservative Aggressive Save | C8: Conservative | D8: Young (25-35) | E8: 32 | F8: 67 | G8: 40000 | H8: 12000 | I8: 0.04 | J8: 0.03 | K8: =F8-E8 -> 35 | L8: =(G8*(1+I8)^K8+H8*(((1+I8)^K8-(1+0.03)^K8)/(I8-0.03)))/(1+J8)^K8 -> 538944.4 | M8: =60000*((1-(1/(1+((1+I8)/(1+J8)-1)))^(90-F8))/((1+I8)/(1+J8)-1)) -> 1231451.4 | N8: =L8-M8 -> -692507.01
B9: Conservative Late Starter | C9: Conservative | D9: Mid-Career (36-45) | E9: 38 | F9: 65 | G9: 80000 | H9: 12000 | I9: 0.04 | J9: 0.025 | K9: =F9-E9 -> 27 | L9: =(G9*(1+I9)^K9+H9*(((1+I9)^K9-(1+0.03)^K9)/(I9-0.03)))/(1+J9)^K9 -> 526319.42 | M9: =60000*((1-(1/(1+((1+I9)/(1+J9)-1)))^(90-F9))/((1+I9)/(1+J9)-1)) -> 1248673.1 | N9: =L9-M9 -> -722353.7
B10: Conservative Catch-Up | C10: Conservative | D10: Mid-Career (36-45) | E10: 40 | F10: 67 | G10: 120000 | H10: 18000 | I10: 0.045 | J10: 0.025 | K10: =F10-E10 -> 27 | L10: =(G10*(1+I10)^K10+H10*(((1+I10)^K10-(1+0.03)^K10)/(I10-0.03)))/(1+J10)^K10 -> 855686.31 | M10: =60000*((1-(1/(1+((1+I10)/(1+J10)-1)))^(90-F10))/((1+I10)/(1+J10)-1)) -> 1103397.6 | N10: =L10-M10 -> -247711.26
B11: Conservative Steady | C11: Conservative | D11: Mid-Career (36-45) | E11: 42 | F11: 65 | G11: 150000 | H11: 15000 | I11: 0.04 | J11: 0.03 | K11: =F11-E11 -> 23 | L11: =(G11*(1+I11)^K11+H11*(((1+I11)^K11-(1+0.03)^K11)/(I11-0.03)))/(1+J11)^K11 -> 560604.2 | M11: =60000*((1-(1/(1+((1+I11)/(1+J11)-1)))^(90-F11))/((1+I11)/(1+J11)-1)) -> 1326158.3 | N11: =L11-M11 -> -765554.08
B12: Conservative High Save | C12: Conservative | D12: Mid-Career (36-45) | E12: 45 | F12: 67 | G12: 200000 | H12: 20000 | I12: 0.045 | J12: 0.025 | K12: =F12-E12 -> 22 | L12: =(G12*(1+I12)^K12+H12*(((1+I12)^K12-(1+0.03)^K12)/(I12-0.03)))/(1+J12)^K12 -> 861690.59 | M12: =60000*((1-(1/(1+((1+I12)/(1+J12)-1)))^(90-F12))/((1+I12)/(1+J12)-1)) -> 1103397.6 | N12: =L12-M12 -> -241706.99
B13: Moderate Early Start | C13: Moderate | D13: Young (25-35) | E13: 25 | F13: 65 | G13: 20000 | H13: 8000 | I13: 0.07 | J13: 0.025 | K13: =F13-E13 -> 40 | L13: =(G13*(1+I13)^K13+H13*(((1+I13)^K13-(1+0.03)^K13)/(I13-0.03)))/(1+J13)^K13 -> 983951.71 | M13: =60000*((1-(1/(1+((1+I13)/(1+J13)-1)))^(90-F13))/((1+I13)/(1+J13)-1)) -> 899830.18 | N13: =L13-M13 -> 84121.537
B14: Moderate Standard | C14: Moderate | D14: Young (25-35) | E14: 30 | F14: 65 | G14: 50000 | H14: 12000 | I14: 0.07 | J14: 0.025 | K14: =F14-E14 -> 35 | L14: =(G14*(1+I14)^K14+H14*(((1+I14)^K14-(1+0.03)^K14)/(I14-0.03)))/(1+J14)^K14 -> 1218876.8 | M14: =60000*((1-(1/(1+((1+I14)/(1+J14)-1)))^(90-F14))/((1+I14)/(1+J14)-1)) -> 899830.18 | N14: =L14-M14 -> 319046.64
B15: Moderate High Save | C15: Moderate | D15: Young (25-35) | E15: 28 | F15: 65 | G15: 35000 | H15: 15000 | I15: 0.065 | J15: 0.025 | K15: =F15-E15 -> 37 | L15: =(G15*(1+I15)^K15+H15*(((1+I15)^K15-(1+0.03)^K15)/(I15-0.03)))/(1+J15)^K15 -> 1397918.8 | M15: =60000*((1-(1/(1+((1+I15)/(1+J15)-1)))^(90-F15))/((1+I15)/(1+J15)-1)) -> 947065.72 | N15: =L15-M15 -> 450853.12
B16: Moderate Late 20s | C16: Moderate | D16: Young (25-35) | E16: 32 | F16: 67 | G16: 45000 | H16: 14000 | I16: 0.07 | J16: 0.03 | K16: =F16-E16 -> 35 | L16: =(G16*(1+I16)^K16+H16*(((1+I16)^K16-(1+0.03)^K16)/(I16-0.03)))/(1+J16)^K16 -> 1148740.5 | M16: =60000*((1-(1/(1+((1+I16)/(1+J16)-1)))^(90-F16))/((1+I16)/(1+J16)-1)) -> 901782.63 | N16: =L16-M16 -> 246957.89
... B28: Aggressive Mid Max | C28: Aggressive | D28: Mid-Career (36-45) | E28: 45 | F28: 67 | G28: 300000 | H28: 30000 | I28: 0.1 | J28: 0.025 | K28: =F28-E28 -> 22 | L28: =(G28*(1+I28)^K28+H28*(((1+I28)^K28-(1+0.03)^K28)/(I28-0.03)))/(1+J28)^K28 -> 2967977.1 | M28: =60000*((1-(1/(1+((1+I28)/(1+J28)-1)))^(90-F28))/((1+I28)/(1+J28)-1)) -> 658403.85 | N28: =L28-M28 -> 2309573.3

Sheet Pivot-Analysis
B1: SCENARIO PIVOT ANALYSIS
B2: Risk Profile | C2: Age Group | D2: Avg Savings at Retirement | E2: Avg Required Nest Egg | F2: Avg Surplus / (Shortfall) | G2: Max Surplus | H2: Min Surplus | I2: # Scenarios
B3: Aggressive | C3: Mid-Career (36-45) | D3: 2342810.7 | E3: 691719.46 | F3: 1651091.2 | G3: 2309573.3 | H3: 1114379.6 | I3: 4
C4: Young (25-35) | D4: 2322425.3 | E4: 697576.92 | F4: 1624848.4 | G4: 2018266.2 | H4: 1327762.1 | I4: 4
B5: Aggressive Total | D5: 2332618 | E5: 694648.19 | F5: 1637969.8 | G5: 2309573.3 | H5: 1114379.6 | I5: 8
B6: Moderate | C6: Mid-Career (36-45) | D6: 1259957.4 | E6: 915716.92 | F6: 344240.52 | G6: 698218.01 | H6: -16858.939 | I6: 4
C7: Young (25-35) | D7: 1187372 | E7: 912127.18 | F7: 275244.8 | G7: 450853.12 | H7: 84121.537 | I7: 4
B8: Moderate Total | D8: 1223664.7 | E8: 913922.05 | F8: 309742.66 | G8: 698218.01 | H8: -16858.939 | I8: 8
B9: Conservative | C9: Mid-Career (36-45) | D9: 701075.13 | E9: 1195406.6 | F9: -494331.51 | G9: -241706.99 | H9: -765554.08 | I9: 4
C10: Young (25-35) | D10: 646307.7 | E10: 1208771.5 | F10: -562463.85 | G10: -298804.06 | H10: -692507.01 | I10: 4
B11: Conservative Total | D11: 673691.41 | E11: 1202089.1 | F11: -528397.68 | G11: -241706.99 | H11: -765554.08 | I11: 8
B12: Grand Total | D12: 1409991.4 | E12: 936886.44 | F12: 473104.93 | G12: 2309573.3 | H12: -765554.08 | I12: 24
